Workbook

Sheet earth
A1: radius | B1: =B5 -> 6378109
A3: radius (mean) | B3: 6371009
A5: radius (SI) | B5: 6378109

Sheet 134527CO
A1: Type | B1: Local Number | C1: Message | D1: Field 1 | E1: Value 1 | F1: Units 1 | G1: Field 2 | H1: Value 2 | I1: Units 2 | J1: Field 3 | K1: Value 3 | L1: Units 3 | M1: Field 4 | N1: Value 4 | O1: Units 4 | P1: Field 5 | Q1: Value 5 | R1: Units 5 | S1: Field 6 | T1: Value 6 | U1: Units 6 | V1: Field 7 | W1: Value 7 | X1: Units 7 | Y1: Field 8 | Z1: Value 8 | AA1: Units 8 | AB1: Field 9 | AC1: Value 9 | AD1: Units 9 | AE1: Field 10 | AF1: Value 10 | AG1: Units 10 | AH1: Field 11 | AI1: Value 11 | AJ1: Units 11 | AK1: Field 12 | AL1: Value 12 | AM1: Units 12 | AN1: Field 13 | AO1: Value 13 | AP1: Units 13 | AQ1: Field 14 | AR1: Value 14 | AS1: Units 14 | AT1: Field 15 | AU1: Value 15 | AV1: Units 15 | AW1: Field 16 | AX1: Value 16 | AY1: Units 16 | AZ1: Field 17 | BA1: Value 17 | BB1: Units 17 | BC1: Field 18 | BD1: Value 18 | BE1: Units 18 | BF1: Field 19 | BG1: Value 19 | BH1: Units 19 | BI1: Field 20 | BJ1: Value 20 | BK1: Units 20 | BL1: Field 21 | BM1: Value 21 | BN1: Units 21 | BO1: Field 22 | BP1: Value 22 | BQ1: Units 22 | BR1: Field 23 | BS1: Value 23 | BT1: Units 23 | BU1: Field 24 | BV1: Value 24 | BW1: Units 24 | BX1: Field 25 | BY1: Value 25 | BZ1: Units 25 | CA1: Field 26 | CB1: Value 26 | CC1: Units 26 | CD1: Field 27 | CE1: Value 27 | CF1: Units 27 | CG1: Field 28 | CH1: Value 28 | CI1: Units 28 | CJ1: Field 29 | CK1: Value 29 | CL1: Units 29 | CM1: Field 30 | CN1: Value 30 | CO1: Units 30 | CP1: Field 31 | CQ1: Value 31 | CR1: Units 31 | CS1: Field 32 | CT1: Value 32 | CU1: Units 32 | CV1: Field 33 | CW1: Value 33 | CX1: Units 33 | CY1: Field 34 | CZ1: Value 34 | DA1: Units 34 | DB1: Field 35 | DC1: Value 35 | DD1: Units 35 | DE1: Field 36 | DF1: Value 36 | DG1: Units 36
A2: Definition | B2: 0 | C2: file_id | D2: serial_number | E2: 1 | G2: time_created | H2: 1 | J2: product_name | K2: 24 | M2: manufacturer | N2: 1 | P2: product | Q2: 1 | S2: number | T2: 1 | V2: type | W2: 1
A3: Data | B3: 0 | C3: file_id | D3: serial_number | E3: 4294967295 | G3: time_created | H3: 1020545186 | J3: product_name | K3: Timex Ironman GPS | M3: manufacturer | N3: 16 | P3: product | Q3: 87 | S3: number | T3: 0 | V3: type | W3: 4
A4: Definition | B4: 15 | C4: unknown | D4: unknown | E4: 2
A5: Definition | B5: 0 | C5: unknown | D5: unknown | E5: 96
A6: Definition | B6: 1 | C6: unknown | D6: unknown | E6: 150
A7: Data | B7: 0 | C7: unknown | D7: unknown | E7: 167|255|81|0|2|80|0|0|64|0|0|0|167|255|81|0|30|20|1|0|0|0|0|0|0|0|0|0|0|0|0|0|0|0|0|0|0|0|0|0|0|0|0|0|0|0|0|0|0|0|0|0|0|0|0|0|0|0|0|0|0|0|0|0|0|0|0|0|0|0|0|0|0|0|0|0|0|0|0|0|0|0|0|0|0|0|0|0|0|0|0|0|0|0|0|0
A8: Data | B8: 1 | C8: unknown | D8: unknown | E8: 216|19|1|0|0|0|0|0|0|0|0|0|0|0|0|0|0|0|0|0|0|0|0|0|0|0|0|0|0|0|0|0|0|0|0|0|0|0|0|0|0|0|0|0|0|0|0|0|0|0|0|0|0|0|0|0|0|0|0|0|0|0|0|0|0|0|0|0|0|0|0|0|0|0|0|0|0|0|0|0|0|0|0|0|0|0|0|0|0|0|0|0|0|0|0|0|0|0|0|0|0|0|0|0|0|0|0|0|0|0|0|0|0|0|0|0|0|0|0|0|0|0|0|0|0|0|0|0|0|0|0|0|0|0|0|0|0|0|0|0|0|0|0|0|0|0|0|0|0|0
A9: Data | B9: 1 | C9: unknown | D9: unknown | E9: 0|0|0|0|0|0|0|0|0|0|0|0|0|0|0|0|0|0|0|0|0|0|0|0|0|0|0|0|0|0|0|0|0|0|0|0|0|0|0|0|0|0|0|0|0|0|0|0|0|0|0|0|0|0|0|0|0|0|0|0|0|0|0|0|0|0|0|0|0|0|0|0|0|0|0|0|0|0|0|0|0|0|0|0|0|0|0|0|0|0|0|0|0|0|0|0|0|0|0|0|0|0|0|0|0|0|0|0|0|0|0|0|0|0|0|0|0|0|0|0|0|0|0|0|0|0|0|0|0|0|0|0|0|0|0|0|0|0|0|0|0|0|0|0|0|0|0|0|0|0
A10: Data | B10: 1 | C10: unknown | D10: unknown | E10: 0|0|0|0|0|0|0|0|0|0|0|0|0|0|0|0|0|0|0|0|0|0|0|0|0|0|0|0|0|0|0|0|0|0|0|0|0|0|0|0|0|0|0|0|0|0|0|0|0|0|0|0|0|0|0|0|0|0|0|0|0|0|0|0|0|0|0|0|0|0|0|0|0|0|0|0|0|0|0|0|0|0|0|0|0|0|0|0|0|0|0|0|0|0|0|0|0|0|0|0|0|0|0|0|0|0|0|0|0|0|0|0|0|0|0|0|0|0|0|0|0|0|0|0|0|0|0|0|0|0|0|0|0|0|0|0|0|0|0|0|0|0|0|0|0|0|0|0|0|0
A11: Data | B11: 1 | C11: unknown | D11: unknown | E11: 0|0|0|0|0|0|0|0|0|0|0|0|0|0|0|0|0|0|0|0|0|0|0|0|0|0|0|0|0|0|0|0|0|0|0|0|0|0|0|0|0|0|0|0|0|0|0|0|0|0|0|0|0|0|0|0|0|0|0|0|0|0|0|0|0|0|0|0|0|0|0|0|0|0|0|0|0|0|0|0|0|0|0|0|0|0|0|0|0|0|0|0|0|0|0|0|0|0|0|0|0|0|0|0|0|0|0|0|0|0|0|0|0|0|0|0|0|0|0|0|0|0|0|0|0|0|0|0|0|0|0|0|0|0|0|0|0|0|0|0|0|0|0|0|0|0|0|0|0|0
A12: Data | B12: 1 | C12: unknown | D12: unknown | E12: 0|0|0|0|0|0|0|0|0|0|0|0|0|0|0|0|0|0|0|0|0|0|0|0|0|0|0|0|0|0|0|0|0|0|0|0|0|0|0|0|0|0|0|0|0|0|0|0|0|0|0|0|0|0|0|0|0|0|0|0|0|0|0|0|0|0|0|0|0|0|0|0|0|0|0|0|0|0|0|0|0|0|0|0|0|0|0|0|0|0|0|0|0|0|0|0|0|0|0|0|0|0|0|0|0|0|0|0|0|0|0|0|0|0|0|0|0|0|0|0|0|0|0|0|0|0|0|0|0|0|0|0|0|0|0|0|0|0|0|0|0|0|0|0|0|0|0|0|0|0
A13: Data | B13: 1 | C13: unknown | D13: unknown | E13: 0|0|0|0|0|0|0|0|0|0|0|0|0|0|0|0|0|0|0|0|0|0|0|0|0|0|0|0|0|0|0|0|0|0|0|0|0|0|0|0|0|0|0|0|0|0|0|0|0|0|0|0|0|0|0|0|0|0|0|0|0|0|0|0|0|0|0|0|0|0|0|0|0|0|0|0|0|0|0|0|0|0|0|0|0|0|0|0|0|0|0|0|0|0|0|0|0|0|0|0|0|0|0|0|0|0|0|0|0|0|0|0|0|0|0|0|0|0|0|0|0|0|0|0|0|0|0|0|0|0|0|0|0|0|0|0|0|0|0|0|0|0|0|0|0|0|0|0|0|0
A14: Data | B14: 15 | C14: unknown | D14: unknown | E14: 44|118
A15: Definition | B15: 0 | C15: record | D15: heart_rate | E15: 1
A16: Definition | B16: 1 | C16: record | D16: cadence | E16: 1
A17: Definition | B17: 2 | C17: record | D17: distance | E17: 1 | G17: unknown | H17: 1 | J17: unknown | K17: 1 | M17: speed | N17: 1
A18: Definition | B18: 3 | C18: record | D18: position_lat | E18: 1 | G18: position_long | H18: 1 | J18: altitude | K18: 1
A19: Definition | B19: 4 | C19: activity | D19: local_timestamp | E19: 1 | G19: num_sessions | H19: 1 | J19: type | K19: 1 | M19: event | N19: 1 | P19: event_type | Q19: 1
A20: Definition | B20: 5 | C20: session | D20: timestamp | E20: 1 | G20: start_time | H20: 1 | J20: total_elapsed_time | K20: 1 | M20: total_timer_time | N20: 1 | P20: total_distance | Q20: 1 | S20: time_in_hr_zone | T20: 1 | V20: time_in_speed_zone | W20: 2 | Y20: time_in_cadence_zone | Z20: 1 | AB20: avg_lap_time | AC20: 1 | AE20: unknown | AF20: 1 | AH20: unknown | AI20: 1 | AK20: unknown | AL20: 1 | AN20: unknown | AO20: 1 | AQ20: unknown | AR20: 1 | AT20: unknown | AU20: 1 | AW20: total_calories | AX20: 1 | AZ20: avg_speed | BA20: 1 | BC20: max_speed | BD20: 1 | BF20: total_ascent | BG20: 1 | BI20: total_descent | BJ20: 1 | BL20: num_laps | BM20: 1 | BO20: avg_altitude | BP20: 1 | BR20: max_altitude | BS20: 1 | BU20: best_lap_index | BV20: 1 | BX20: min_altitude | BY20: 1 | CA20: unknown | CB20: 1 | CD20: unknown | CE20: 1 | CG20: event | CH20: 1 | CJ20: event_type | CK20: 1 | CM20: sport | CN20: 1 | CP20: sub_sport | CQ20: 1 | CS20: avg_heart_rate | CT20: 1 | CV20: max_heart_rate | CW20: 1 | CY20: avg_cadence | CZ20: 1 | DB20: max_cadence | DC20: 1 | DE20: min_heart_rate | DF20: 1
A21: Definition | B21: 6 | C21: lap | D21: timestamp | E21: 1 | G21: start_time | H21: 1 | J21: total_elapsed_time | K21: 1 | M21: total_timer_time | N21: 1 | P21: total_distance | Q21: 1 | S21: time_in_hr_zone | T21: 1 | V21: time_in_speed_zone | W21: 1 | Y21: time_in_cadence_zone | Z21: 1 | AB21: unknown | AC21: 1 | AE21: unknown | AF21: 1 | AH21: unknown | AI21: 1 | AK21: message_index | AL21: 1 | AN21: total_calories | AO21: 1 | AQ21: avg_speed | AR21: 1 | AT21: max_speed | AU21: 1 | AW21: total_ascent | AX21: 1 | AZ21: total_descent | BA21: 1 | BC21: repetition_num | BD21: 1 | BF21: wkt_step_index | BG21: 1 | BI21: event | BJ21: 1 | BL21: event_type | BM21: 1 | BO21: avg_heart_rate | BP21: 1 | BR21: max_heart_rate | BS21: 1 | BU21: avg_cadence | BV21: 1 | BX21: max_cadence | BY21: 1 | CA21: intensity | CB21: 1 | CD21: lap_trigger | CE21: 1 | CG21: min_heart_rate | CH21: 1
A22: Definition | B22: 7 | C22: event | D22: timestamp | E22: 1 | G22: data | H22: 1 | J22: data16 | K22: 1 | M22: event | N22: 1 | P22: event_type | Q22: 1 | S22: event_group | T22: 1
A23: Definition | B23: 8 | C23: unknown | D23: unknown | E23: 1 | G23: unknown | H23: 80
A24: Definition | B24: 9 | C24: record | D24: timestamp | E24: 1
A25: Data | B25: 7 | C25: event | D25: timestamp | E25: 1020545188 | F25: s | G25: event | H25: 0 | J25: event_type | K25: 0
A26: Data | B26: 8 | C26: unknown | D26: unknown | E26: 1020545188 | G26: unknown | H26: RSOC:100;TSOC:100;VOLT:4103;
A27: Data | B27: 8 | C27: unknown | D27: unknown | E27: 1020545188 | G27: unknown | H27: XLINK:4.0.R10.0;SDK:0.36.0001R;GPS:1.3.68;EPH:4/22/2022;
A28: Data | B28: 8 | C28: unknown | D28: unknown | E28: 1020545188 | G28: unknown | H28: DeviceID:27002300045034485032312000000000;
A29: Data | B29: 2 | C29: record | D29: timestamp | E29: 1020545188 | F29: s | G29: distance | H29: 19.1 | I29: m | J29: unknown | K29: 154297 | M29: unknown | N29: 1219512 | P29: speed | Q29: 0.61 | R29: m/s | S29: enhanced_speed | T29: 0.61 | U29: m/s
A30: Data | B30: 3 | C30: record | D30: timestamp | E30: 1020545188 | F30: s | G30: position_lat | H30: 549060544 | I30: semicircles | J30: position_long | K30: -1419059712 | L30: semicircles | M30: altitude | N30: 140 | O30: m | P30: enhanced_altitude | Q30: 140 | R30: m
A31: Data | B31: 2 | C31: record | D31: timestamp | E31: 1020545190 | F31: s | G31: distance | H31: 22.4 | I31: m | J31: unknown | K31: 222717 | M31: unknown | N31: 1219512 | P31: speed | Q31: 0.82 | R31: m/s | S31: enhanced_speed | T31: 0.82 | U31: m/s
A32: Data | B32: 3 | C32: record | D32: timestamp | E32: 1020545190 | F32: s | G32: position_lat | H32: 549060160 | I32: semicircles | J32: position_long | K32: -1419060224 | L32: semicircles | M32: altitude | N32: 138 | O32: m | P32: enhanced_altitude | Q32: 138 | R32: m
A33: Data | B33: 2 | C33: record | D33: timestamp | E33: 1020545193 | F33: s | G33: distance | H33: 24.8 | I33: m | J33: unknown | K33: 283687 | M33: unknown | N33: 892857 | P33: speed | Q33: 1.12 | R33: m/s | S33: enhanced_speed | T33: 1.12 | U33: m/s
A34: Data | B34: 3 | C34: record | D34: timestamp | E34: 1020545193 | F34: s | G34: position_lat | H34: 549060032 | I34: semicircles | J34: position_long | K34: -1419060352 | L34: semicircles | M34: altitude | N34: 137 | O34: m | P34: enhanced_altitude | Q34: 137 | R34: m
A35: Data | B35: 2 | C35: record | D35: timestamp | E35: 1020545195 | F35: s | G35: distance | H35: 27.1 | I35: m | J35: unknown | K35: 335008 | M35: unknown | N35: 892857 | P35: speed | Q35: 1.12 | R35: m/s | S35: enhanced_speed | T35: 1.12 | U35: m/s
A36: Data | B36: 3 | C36: record | D36: timestamp | E36: 1020545195 | F36: s | G36: position_lat | H36: 549059840 | I36: semicircles | J36: position_long | K36: -1419060864 | L36: semicircles | M36: altitude | N36: 137 | O36: m | P36: enhanced_altitude | Q36: 137 | R36: m
A37: Data | B37: 2 | C37: record | D37: timestamp | E37: 1020545197 | F37: s | G37: distance | H37: 29.6 | I37: m | J37: unknown | K37: 376506 | M37: unknown | N37: 854700 | P37: speed | Q37: 1.17 | R37: m/s | S37: enhanced_speed | T37: 1.17 | U37: m/s
A38: Data | B38: 3 | C38: record | D38: timestamp | E38: 1020545197 | F38: s | G38: position_lat | H38: 549060032 | I38: semicircles | J38: position_long | K38: -1419061248 | L38: semicircles | M38: altitude | N38: 136 | O38: m | P38: enhanced_altitude | Q38: 136 | R38: m
A39: Data | B39: 2 | C39: record | D39: timestamp | E39: 1020545199 | F39: s | G39: distance | H39: 29.9 | I39: m | J39: unknown | K39: 441111 | M39: unknown | N39: 840336 | P39: speed | Q39: 1.19 | R39: m/s | S39: enhanced_speed | T39: 1.19 | U39: m/s
A40: Data | B40: 3 | C40: record | D40: timestamp | E40: 1020545199 | F40: s | G40: position_lat | H40: 549060032 | I40: semicircles | J40: position_long | K40: -1419061248 | L40: semicircles | M40: altitude | N40: 135 | O40: m | P40: enhanced_altitude | Q40: 135 | R40: m
...

Sheet gps_speeds
M1: mph
A2: unknown | B2: 154297 | D2: unknown | E2: 1219512 | G2: speed | H2: 0.61 | I2: m/s | J2: enhanced_speed | K2: 0.61 | L2: m/s | M2: =K2*3600/1609.344 -> 1.3645311
A3: unknown | B3: 222717 | D3: unknown | E3: 1219512 | G3: speed | H3: 0.82 | I3: m/s | J3: enhanced_speed | K3: 0.82 | L3: m/s | M3: =K3*3600/1609.344 -> 1.8342878
A4: unknown | B4: 283687 | D4: unknown | E4: 892857 | G4: speed | H4: 1.12 | I4: m/s | J4: enhanced_speed | K4: 1.12 | L4: m/s | M4: =K4*3600/1609.344 -> 2.5053686
A5: unknown | B5: 335008 | D5: unknown | E5: 892857 | G5: speed | H5: 1.12 | I5: m/s | J5: enhanced_speed | K5: 1.12 | L5: m/s | M5: =K5*3600/1609.344 -> 2.5053686
A6: unknown | B6: 376506 | D6: unknown | E6: 854700 | G6: speed | H6: 1.17 | I6: m/s | J6: enhanced_speed | K6: 1.17 | L6: m/s | M6: =K6*3600/1609.344 -> 2.6172155
A7: unknown | B7: 441111 | D7: unknown | E7: 840336 | G7: speed | H7: 1.19 | I7: m/s | J7: enhanced_speed | K7: 1.19 | L7: m/s | M7: =K7*3600/1609.344 -> 2.6619542
A8: unknown | B8: 509684 | D8: unknown | E8: 840336 | G8: speed | H8: 0.97 | I8: m/s | J8: enhanced_speed | K8: 0.97 | L8: m/s | M8: =K8*3600/1609.344 -> 2.1698282
A9: unknown | B9: 578034 | D9: unknown | E9: 840336 | G9: speed | H9: 0.97 | I9: m/s | J9: enhanced_speed | K9: 0.97 | L9: m/s | M9: =K9*3600/1609.344 -> 2.1698282
A10: unknown | B10: 646412 | D10: unknown | E10: 840336 | G10: speed | H10: 0 | I10: m/s | J10: enhanced_speed | K10: 0 | L10: m/s | M10: =K10*3600/1609.344 -> 0
A11: unknown | B11: 714796 | D11: unknown | E11: 840336 | G11: speed | H11: 0.97 | I11: m/s | J11: enhanced_speed | K11: 0.97 | L11: m/s | M11: =K11*3600/1609.344 -> 2.1698282
A12: unknown | B12: 783699 | D12: unknown | E12: 840336 | G12: speed | H12: 0.97 | I12: m/s | J12: enhanced_speed | K12: 0.97 | L12: m/s | M12: =K12*3600/1609.344 -> 2.1698282
A13: unknown | B13: 851788 | D13: unknown | E13: 840336 | G13: speed | H13: 1.06 | I13: m/s | J13: enhanced_speed | K13: 1.06 | L13: m/s | M13: =K13*3600/1609.344 -> 2.3711525
... A2620: unknown | B2620: 294464 | D2620: unknown | E2620: 117924 | G2620: speed | H2620: 0.15 | I2620: m/s | J2620: enhanced_speed | K2620: 0.15 | L2620: m/s | M2620: =K2620*3600/1609.344 -> 0.33554044

Sheet pos_speeds
R1: lat | S1: lon | T1: yoff | U1: xscale | W1: tdelta | X1: ydelta | Y1: longdelta | Z1: xdelta | AA1: zdelta | AB1: dist (3d) | AC1: m/s | AE1: time | AF1: mph | AG1: ma
A2: timestamp | B2: 1020545188 | C2: s | D2: position_lat | E2: 549060544 | F2: semicircles | G2: position_long | H2: -1419059712 | I2: semicircles | J2: altitude | K2: 140 | L2: m | M2: enhanced_altitude | N2: 140 | O2: m | R2: =RADIANS(E2* (180 / 2 ^31)) -> 0.8032306 | S2: =RADIANS(H2* (180 / 2 ^31)) -> -2.0759681 | T2: =R2*earth!$B$1 -> 5123092.3 | U2: =COS(R2)*earth!$B$1 -> 4428867
A3: timestamp | B3: 1020545190 | C3: s | D3: position_lat | E3: 549060160 | F3: semicircles | G3: position_long | H3: -1419060224 | I3: semicircles | J3: altitude | K3: 138 | L3: m | M3: enhanced_altitude | N3: 138 | O3: m | P3: =B3-B2 -> 2 | R3: =RADIANS(E3* (180 / 2 ^31)) -> 0.80323003 | S3: =RADIANS(H3* (180 / 2 ^31)) -> -2.0759689 | T3: =R3*earth!$B$1 -> 5123088.7 | U3: =COS(R3)*earth!$B$1 -> 4428869.6 | W3: =B3-B2 -> 2 | X3: =T3-T2 -> -3.58297 | Y3: =S3-S2 -> -7.4901406e-07 | Z3: =Y3*U3 -> -3.3172856 | AA3: =N3-N2 -> -2 | AB3: =SQRT(X3*X3+Z3*Z3+AA3*AA3) -> 5.2765573 | AC3: =AB3/W3 -> 2.6382787 | AE3: =B3-$B$2 -> 2 | AF3: =AC3*3600/1609.344 -> 5.9016613
A4: timestamp | B4: 1020545193 | C4: s | D4: position_lat | E4: 549060032 | F4: semicircles | G4: position_long | H4: -1419060352 | I4: semicircles | J4: altitude | K4: 137 | L4: m | M4: enhanced_altitude | N4: 137 | O4: m | P4: =B4-B3 -> 3 | R4: =RADIANS(E4* (180 / 2 ^31)) -> 0.80322985 | S4: =RADIANS(H4* (180 / 2 ^31)) -> -2.075969 | T4: =R4*earth!$B$1 -> 5123087.5 | U4: =COS(R4)*earth!$B$1 -> 4428870.4 | W4: =B4-B3 -> 3 | X4: =T4-T3 -> -1.1943233 | Y4: =S4-S3 -> -1.8725351e-07 | Z4: =Y4*U4 -> -0.82932155 | AA4: =N4-N3 -> -1 | AB4: =SQRT(X4*X4+Z4*Z4+AA4*AA4) -> 1.7647046 | AC4: =AB4/W4 -> 0.58823488 | AE4: =B4-$B$2 -> 5 | AF4: =AC4*3600/1609.344 -> 1.3158439 | AG4: =AVERAGE(AF3:AF5) -> 3.8114218
A5: timestamp | B5: 1020545195 | C5: s | D5: position_lat | E5: 549059840 | F5: semicircles | G5: position_long | H5: -1419060864 | I5: semicircles | J5: altitude | K5: 137 | L5: m | M5: enhanced_altitude | N5: 137 | O5: m | P5: =B5-B4 -> 2 | R5: =RADIANS(E5* (180 / 2 ^31)) -> 0.80322957 | S5: =RADIANS(H5* (180 / 2 ^31)) -> -2.0759698 | T5: =R5*earth!$B$1 -> 5123085.7 | U5: =COS(R5)*earth!$B$1 -> 4428871.7 | W5: =B5-B4 -> 2 | X5: =T5-T4 -> -1.791485 | Y5: =S5-S4 -> -7.4901406e-07 | Z5: =Y5*U5 -> -3.3172872 | AA5: =N5-N4 -> 0 | AB5: =SQRT(X5*X5+Z5*Z5+AA5*AA5) -> 3.770121 | AC5: =AB5/W5 -> 1.8850605 | AE5: =B5-$B$2 -> 7 | AF5: =AC5*3600/1609.344 -> 4.2167603 | AG5: =AVERAGE(AF4:AF6) -> 3.0464831
A6: timestamp | B6: 1020545197 | C6: s | D6: position_lat | E6: 549060032 | F6: semicircles | G6: position_long | H6: -1419061248 | I6: semicircles | J6: altitude | K6: 136 | L6: m | M6: enhanced_altitude | N6: 136 | O6: m | P6: =B6-B5 -> 2 | R6: =RADIANS(E6* (180 / 2 ^31)) -> 0.80322985 | S6: =RADIANS(H6* (180 / 2 ^31)) -> -2.0759704 | T6: =R6*earth!$B$1 -> 5123087.5 | U6: =COS(R6)*earth!$B$1 -> 4428870.4 | W6: =B6-B5 -> 2 | X6: =T6-T5 -> 1.791485 | Y6: =S6-S5 -> -5.6176054e-07 | Z6: =Y6*U6 -> -2.4879646 | AA6: =N6-N5 -> -1 | AB6: =SQRT(X6*X6+Z6*Z6+AA6*AA6) -> 3.224808 | AC6: =AB6/W6 -> 1.612404 | AE6: =B6-$B$2 -> 9 | AF6: =AC6*3600/1609.344 -> 3.606845 | AG6: =AVERAGE(AF5:AF7) -> 2.9806911
A7: timestamp | B7: 1020545199 | C7: s | D7: position_lat | E7: 549060032 | F7: semicircles | G7: position_long | H7: -1419061248 | I7: semicircles | J7: altitude | K7: 135 | L7: m | M7: enhanced_altitude | N7: 135 | O7: m | P7: =B7-B6 -> 2 | R7: =RADIANS(E7* (180 / 2 ^31)) -> 0.80322985 | S7: =RADIANS(H7* (180 / 2 ^31)) -> -2.0759704 | T7: =R7*earth!$B$1 -> 5123087.5 | U7: =COS(R7)*earth!$B$1 -> 4428870.4 | W7: =B7-B6 -> 2 | X7: =T7-T6 -> 0 | Y7: =S7-S6 -> 0 | Z7: =Y7*U7 -> 0 | AA7: =N7-N6 -> -1 | AB7: =SQRT(X7*X7+Z7*Z7+AA7*AA7) -> 1 | AC7: =AB7/W7 -> 0.5 | AE7: =B7-$B$2 -> 11 | AF7: =AC7*3600/1609.344 -> 1.1184681 | AG7: =AVERAGE(AF6:AF8) -> 2.0093432
A8: timestamp | B8: 1020545201 | C8: s | D8: position_lat | E8: 549060096 | F8: semicircles | G8: position_long | H8: -1419061248 | I8: semicircles | J8: altitude | K8: 134 | L8: m | M8: enhanced_altitude | N8: 134 | O8: m | P8: =B8-B7 -> 2 | R8: =RADIANS(E8* (180 / 2 ^31)) -> 0.80322994 | S8: =RADIANS(H8* (180 / 2 ^31)) -> -2.0759704 | T8: =R8*earth!$B$1 -> 5123088.1 | U8: =COS(R8)*earth!$B$1 -> 4428870 | W8: =B8-B7 -> 2 | X8: =T8-T7 -> 0.59716166 | Y8: =S8-S7 -> 0 | Z8: =Y8*U8 -> 0 | AA8: =N8-N7 -> -1 | AB8: =SQRT(X8*X8+Z8*Z8+AA8*AA8) -> 1.1647326 | AC8: =AB8/W8 -> 0.5823663 | AE8: =B8-$B$2 -> 13 | AF8: =AC8*3600/1609.344 -> 1.3027163 | AG8: =AVERAGE(AF7:AF9) -> 1.0296969
A9: timestamp | B9: 1020545203 | C9: s | D9: position_lat | E9: 549060160 | F9: semicircles | G9: position_long | H9: -1419061248 | I9: semicircles | J9: altitude | K9: 134 | L9: m | M9: enhanced_altitude | N9: 134 | O9: m | P9: =B9-B8 -> 2 | R9: =RADIANS(E9* (180 / 2 ^31)) -> 0.80323003 | S9: =RADIANS(H9* (180 / 2 ^31)) -> -2.0759704 | T9: =R9*earth!$B$1 -> 5123088.7 | U9: =COS(R9)*earth!$B$1 -> 4428869.6 | W9: =B9-B8 -> 2 | X9: =T9-T8 -> 0.59716166 | Y9: =S9-S8 -> 0 | Z9: =Y9*U9 -> 0 | AA9: =N9-N8 -> 0 | AB9: =SQRT(X9*X9+Z9*Z9+AA9*AA9) -> 0.59716166 | AC9: =AB9/W9 -> 0.29858083 | AE9: =B9-$B$2 -> 15 | AF9: =AC9*3600/1609.344 -> 0.6679063 | AG9: =AVERAGE(AF8:AF10) -> 1.0296969
A10: timestamp | B10: 1020545205 | C10: s | D10: position_lat | E10: 549060160 | F10: semicircles | G10: position_long | H10: -1419061248 | I10: semicircles | J10: altitude | K10: 133 | L10: m | M10: enhanced_altitude | N10: 133 | O10: m | P10: =B10-B9 -> 2 | R10: =RADIANS(E10* (180 / 2 ^31)) -> 0.80323003 | S10: =RADIANS(H10* (180 / 2 ^31)) -> -2.0759704 | T10: =R10*earth!$B$1 -> 5123088.7 | U10: =COS(R10)*earth!$B$1 -> 4428869.6 | W10: =B10-B9 -> 2 | X10: =T10-T9 -> 0 | Y10: =S10-S9 -> 0 | Z10: =Y10*U10 -> 0 | AA10: =N10-N9 -> -1 | AB10: =SQRT(X10*X10+Z10*Z10+AA10*AA10) -> 1 | AC10: =AB10/W10 -> 0.5 | AE10: =B10-$B$2 -> 17 | AF10: =AC10*3600/1609.344 -> 1.1184681 | AG10: =AVERAGE(AF9:AF11) -> 0.96828086
A11: timestamp | B11: 1020545207 | C11: s | D11: position_lat | E11: 549060160 | F11: semicircles | G11: position_long | H11: -1419061248 | I11: semicircles | J11: altitude | K11: 132 | L11: m | M11: enhanced_altitude | N11: 132 | O11: m | P11: =B11-B10 -> 2 | R11: =RADIANS(E11* (180 / 2 ^31)) -> 0.80323003 | S11: =RADIANS(H11* (180 / 2 ^31)) -> -2.0759704 | T11: =R11*earth!$B$1 -> 5123088.7 | U11: =COS(R11)*earth!$B$1 -> 4428869.6 | W11: =B11-B10 -> 2 | X11: =T11-T10 -> 0 | Y11: =S11-S10 -> 0 | Z11: =Y11*U11 -> 0 | AA11: =N11-N10 -> -1 | AB11: =SQRT(X11*X11+Z11*Z11+AA11*AA11) -> 1 | AC11: =AB11/W11 -> 0.5 | AE11: =B11-$B$2 -> 19 | AF11: =AC11*3600/1609.344 -> 1.1184681 | AG11: =AVERAGE(AF10:AF12) -> 1.1184681
A12: timestamp | B12: 1020545209 | C12: s | D12: position_lat | E12: 549060160 | F12: semicircles | G12: position_long | H12: -1419061248 | I12: semicircles | J12: altitude | K12: 131 | L12: m | M12: enhanced_altitude | N12: 131 | O12: m | P12: =B12-B11 -> 2 | R12: =RADIANS(E12* (180 / 2 ^31)) -> 0.80323003 | S12: =RADIANS(H12* (180 / 2 ^31)) -> -2.0759704 | T12: =R12*earth!$B$1 -> 5123088.7 | U12: =COS(R12)*earth!$B$1 -> 4428869.6 | W12: =B12-B11 -> 2 | X12: =T12-T11 -> 0 | Y12: =S12-S11 -> 0 | Z12: =Y12*U12 -> 0 | AA12: =N12-N11 -> -1 | AB12: =SQRT(X12*X12+Z12*Z12+AA12*AA12) -> 1 | AC12: =AB12/W12 -> 0.5 | AE12: =B12-$B$2 -> 21 | AF12: =AC12*3600/1609.344 -> 1.1184681 | AG12: =AVERAGE(AF11:AF13) -> 2.8754996
A13: timestamp | B13: 1020545211 | C13: s | D13: position_lat | E13: 549060736 | F13: semicircles | G13: position_long | H13: -1419060992 | I13: semicircles | J13: altitude | K13: 132 | L13: m | M13: enhanced_altitude | N13: 132 | O13: m | P13: =B13-B12 -> 2 | R13: =RADIANS(E13* (180 / 2 ^31)) -> 0.80323088 | S13: =RADIANS(H13* (180 / 2 ^31)) -> -2.07597 | T13: =R13*earth!$B$1 -> 5123094.1 | U13: =COS(R13)*earth!$B$1 -> 4428865.7 | W13: =B13-B12 -> 2 | X13: =T13-T12 -> 5.374455 | Y13: =S13-S12 -> 3.7450703e-07 | Z13: =Y13*U13 -> 1.6586413 | AA13: =N13-N12 -> 1 | AB13: =SQRT(X13*X13+Z13*Z13+AA13*AA13) -> 5.7127802 | AC13: =AB13/W13 -> 2.8563901 | AE13: =B13-$B$2 -> 23 | AF13: =AC13*3600/1609.344 -> 6.3895626 | AG13: =AVERAGE(AF12:AF14) -> 9.3782932
A14: timestamp | B14: 1020545213 | C14: s | D14: position_lat | E14: 549062336 | F14: semicircles | G14: position_long | H14: -1419059328 | I14: semicircles | J14: altitude | K14: 133 | L14: m | M14: enhanced_altitude | N14: 133 | O14: m | P14: =B14-B13 -> 2 | R14: =RADIANS(E14* (180 / 2 ^31)) -> 0.80323322 | S14: =RADIANS(H14* (180 / 2 ^31)) -> -2.0759675 | T14: =R14*earth!$B$1 -> 5123109 | U14: =COS(R14)*earth!$B$1 -> 4428854.9 | W14: =B14-B13 -> 2 | X14: =T14-T13 -> 14.929042 | Y14: =S14-S13 -> 2.4342957e-06 | Z14: =Y14*U14 -> 10.781142 | AA14: =N14-N13 -> 1 | AB14: =SQRT(X14*X14+Z14*Z14+AA14*AA14) -> 18.442053 | AC14: =AB14/W14 -> 9.2210264 | AE14: =B14-$B$2 -> 25 | AF14: =AC14*3600/1609.344 -> 20.626849 | AG14: =AVERAGE(AF13:AF15) -> 10.501645
A15: timestamp | B15: 1020545215 | C15: s | D15: position_lat | E15: 549062656 | F15: semicircles | G15: position_long | H15: -1419059712 | I15: semicircles | J15: altitude | K15: 134 | L15: m | M15: enhanced_altitude | N15: 134 | O15: m | P15: =B15-B14 -> 2 | R15: =RADIANS(E15* (180 / 2 ^31)) -> 0.80323369 | S15: =RADIANS(H15* (180 / 2 ^31)) -> -2.0759681 | T15: =R15*earth!$B$1 -> 5123112 | U15: =COS(R15)*earth!$B$1 -> 4428852.8 | W15: =B15-B14 -> 2 | X15: =T15-T14 -> 2.9858083 | Y15: =S15-S14 -> -5.6176054e-07 | Z15: =Y15*U15 -> -2.4879547 | AA15: =N15-N14 -> 1 | AB15: =SQRT(X15*X15+Z15*Z15+AA15*AA15) -> 4.0130998 | AC15: =AB15/W15 -> 2.0065499 | AE15: =B15-$B$2 -> 27 | AF15: =AC15*3600/1609.344 -> 4.4885243 | AG15: =AVERAGE(AF14:AF16) -> 9.1367064
... A2618: timestamp | B2618: 1020550553 | C2618: s | D2618: position_lat | E2618: 549073408 | F2618: semicircles | G2618: position_long | H2618: -1419043840 | I2618: semicircles | J2618: altitude | K2618: 111 | L2618: m | M2618: enhanced_altitude | N2618: 111 | O2618: m | P2618: =B2618-B2617 -> 2 | R2618: =RADIANS(E2618* (180 / 2 ^31)) -> 0.80324942 | S2618: =RADIANS(H2618* (180 / 2 ^31)) -> -2.0759449 | T2618: =R2618*earth!$B$1 -> 5123212.3 | U2618: =COS(R2618)*earth!$B$1 -> 4428780.6 | W2618: =B2618-B2617 -> 2 | X2618: =T2618-T2617 -> 0 | Y2618: =S2618-S2617 -> 0 | Z2618: =Y2618*U2618 -> 0 | AA2618: =N2618-N2617 -> 0 | AB2618: =SQRT(X2618*X2618+Z2618*Z2618+AA2618*AA2618) -> 0 | AC2618: =AB2618/W2618 -> 0 | AE2618: =B2618-$B$2 -> 5365 | AF2618: =AC2618*3600/1609.344 -> 0 | AG2618: =AVERAGE(AF2617:AF2619) -> 0
A2619: timestamp | B2619: 1020550555 | C2619: s | D2619: position_lat | E2619: 549073408 | F2619: semicircles | G2619: position_long | H2619: -1419043840 | I2619: semicircles | J2619: altitude | K2619: 111 | L2619: m | M2619: enhanced_altitude | N2619: 111 | O2619: m | P2619: =B2619-B2618 -> 2 | R2619: =RADIANS(E2619* (180 / 2 ^31)) -> 0.80324942 | S2619: =RADIANS(H2619* (180 / 2 ^31)) -> -2.0759449 | T2619: =R2619*earth!$B$1 -> 5123212.3 | U2619: =COS(R2619)*earth!$B$1 -> 4428780.6 | W2619: =B2619-B2618 -> 2 | X2619: =T2619-T2618 -> 0 | Y2619: =S2619-S2618 -> 0 | Z2619: =Y2619*U2619 -> 0 | AA2619: =N2619-N2618 -> 0 | AB2619: =SQRT(X2619*X2619+Z2619*Z2619+AA2619*AA2619) -> 0 | AC2619: =AB2619/W2619 -> 0 | AE2619: =B2619-$B$2 -> 5367 | AF2619: =AC2619*3600/1609.344 -> 0
P2621: =MIN(P3:P2619) -> 2
AA2622: distance | AB2622: =SUM(AB3:AB2619)/1609.344 -> 11.639181 | AE2622: max | AF2622: =MAX(AF3:AF2619) -> 28.355138 | AG2622: =MAX(AG3:AG2619) -> 21.994318

Sheet sorted_pos_speeds
A1: 0
A2: 0
A3: 0
A4: 0
A5: 0
A6: 0
A7: 0
A8: 0
A9: 0
A10: 0
A11: 0
A12: 0
... A2617: 28.323623
A2619: =A2591 -> 22.484047 | B2619: ignore 1%

Sheet charts
